Workbook

Sheet SampleSuperstore
A1: Ship Mode | B1: Segment | C1: Country | D1: City | E1: State | F1: Postal Code | G1: Region | H1: Category | I1: Sub-Category | J1: Sales | K1: Quantity | L1: Discount | M1: Profit
A2: Second Class | B2: Consumer | C2: United States | D2: Henderson | E2: Kentucky | F2: 42420 | G2: South | H2: Furniture | I2: Bookcases | J2: 26196 | K2: 2 | L2: 0 | M2: 419136
A3: Second Class | B3: Consumer | C3: United States | D3: Henderson | E3: Kentucky | F3: 42420 | G3: South | H3: Furniture | I3: Chairs | J3: 73194 | K3: 3 | L3: 0 | M3: 219582
A4: Second Class | B4: Corporate | C4: United States | D4: Los Angeles | E4: California | F4: 90036 | G4: West | H4: Office Supplies | I4: Labels | J4: 1462 | K4: 2 | L4: 0 | M4: 68714
A5: Standard Class | B5: Consumer | C5: United States | D5: Fort Lauderdale | E5: Florida | F5: 33311 | G5: South | H5: Furniture | I5: Tables | J5: 9575775 | K5: 5 | L5: 45 | M5: -383031
A6: Standard Class | B6: Consumer | C6: United States | D6: Fort Lauderdale | E6: Florida | F6: 33311 | G6: South | H6: Office Supplies | I6: Storage | J6: 22368 | K6: 2 | L6: 2 | M6: 25164
A7: Standard Class | B7: Consumer | C7: United States | D7: Los Angeles | E7: California | F7: 90032 | G7: West | H7: Furniture | I7: Furnishings | J7: 4886 | K7: 7 | L7: 0 | M7: 141694
A8: Standard Class | B8: Consumer | C8: United States | D8: Los Angeles | E8: California | F8: 90032 | G8: West | H8: Office Supplies | I8: Art | J8: 728 | K8: 4 | L8: 0 | M8: 19656
A9: Standard Class | B9: Consumer | C9: United States | D9: Los Angeles | E9: California | F9: 90032 | G9: West | H9: Technology | I9: Phones | J9: 907152 | K9: 6 | L9: 2 | M9: 907152
A10: Standard Class | B10: Consumer | C10: United States | D10: Los Angeles | E10: California | F10: 90032 | G10: West | H10: Office Supplies | I10: Binders | J10: 18504 | K10: 3 | L10: 2 | M10: 57825
A11: Standard Class | B11: Consumer | C11: United States | D11: Los Angeles | E11: California | F11: 90032 | G11: West | H11: Office Supplies | I11: Appliances | J11: 1149 | K11: 5 | L11: 0 | M11: 3447
A12: Standard Class | B12: Consumer | C12: United States | D12: Los Angeles | E12: California | F12: 90032 | G12: West | H12: Furniture | I12: Tables | J12: 1706184 | K12: 9 | L12: 2 | M12: 853092
A13: Standard Class | B13: Consumer | C13: United States | D13: Los Angeles | E13: California | F13: 90032 | G13: West | H13: Technology | I13: Phones | J13: 911424 | K13: 4 | L13: 2 | M13: 683568
... A9995: Second Class | B9995: Consumer | C9995: United States | D9995: Westminster | E9995: California | F9995: 92683 | G9995: West | H9995: Office Supplies | I9995: Appliances | J9995: 24316 | K9995: 2 | L9995: 0 | M9995: 72948

Sheet VLookUp
A1: Unique Postal Code | B1: Region
A2: {=_xlfn.UNIQUE(SampleSuperstore[Postal Code])} -> 42420 | B2: =VLOOKUP(A2,SampleSuperstore[[Postal Code]:[Profit]],2,0) -> South
A3: 90036 | B3: =VLOOKUP(A3,SampleSuperstore[[Postal Code]:[Profit]],2,0) -> West
A4: 33311 | B4: =VLOOKUP(A4,SampleSuperstore[[Postal Code]:[Profit]],2,0) -> South
A5: 90032 | B5: =VLOOKUP(A5,SampleSuperstore[[Postal Code]:[Profit]],2,0) -> West
A6: 28027 | B6: =VLOOKUP(A6,SampleSuperstore[[Postal Code]:[Profit]],2,0) -> South
A7: 98103 | B7: =VLOOKUP(A7,SampleSuperstore[[Postal Code]:[Profit]],2,0) -> West
A8: 76106 | B8: =VLOOKUP(A8,SampleSuperstore[[Postal Code]:[Profit]],2,0) -> Central
A9: 53711 | B9: =VLOOKUP(A9,SampleSuperstore[[Postal Code]:[Profit]],2,0) -> Central
A10: 84084 | B10: =VLOOKUP(A10,SampleSuperstore[[Postal Code]:[Profit]],2,0) -> West
A11: 94109 | B11: =VLOOKUP(A11,SampleSuperstore[[Postal Code]:[Profit]],2,0) -> West
A12: 68025 | B12: =VLOOKUP(A12,SampleSuperstore[[Postal Code]:[Profit]],2,0) -> Central
A13: 19140 | B13: =VLOOKUP(A13,SampleSuperstore[[Postal Code]:[Profit]],2,0) -> East
A14: 84057 | B14: =VLOOKUP(A14,SampleSuperstore[[Postal Code]:[Profit]],2,0) -> West
... A632: 30188 | B632: =VLOOKUP(A632,SampleSuperstore[[Postal Code]:[Profit]],2,0) -> South

Sheet Index + Match
A1: Unique Postal Code | B1: Row_Number | C1: Region | F1: Unique Postal Code | G1: City
A2: {=_xlfn.UNIQUE(SampleSuperstore[Postal Code])} -> 42420 | B2: =MATCH(A2,SampleSuperstore[Postal Code],0) -> 1 | C2: {=INDEX(SampleSuperstore[Region],'Index + Match'!B2)} -> South | F2: {=_xlfn.UNIQUE(SampleSuperstore[Postal Code])} -> 42420 | G2: =INDEX(SampleSuperstore[City],MATCH('Index + Match'!F2,SampleSuperstore[Postal Code],0)) -> Henderson
A3: 90036 | B3: =MATCH(A3,SampleSuperstore[Postal Code],0) -> 3 | C3: {=INDEX(SampleSuperstore[Region],'Index + Match'!B3)} -> West | F3: 90036 | G3: =INDEX(SampleSuperstore[City],MATCH('Index + Match'!F3,SampleSuperstore[Postal Code],0)) -> Los Angeles
A4: 33311 | B4: =MATCH(A4,SampleSuperstore[Postal Code],0) -> 4 | C4: {=INDEX(SampleSuperstore[Region],'Index + Match'!B4)} -> South | F4: 33311 | G4: =INDEX(SampleSuperstore[City],MATCH('Index + Match'!F4,SampleSuperstore[Postal Code],0)) -> Fort Lauderdale
A5: 90032 | B5: =MATCH(A5,SampleSuperstore[Postal Code],0) -> 6 | C5: {=INDEX(SampleSuperstore[Region],'Index + Match'!B5)} -> West | F5: 90032 | G5: =INDEX(SampleSuperstore[City],MATCH('Index + Match'!F5,SampleSuperstore[Postal Code],0)) -> Los Angeles
A6: 28027 | B6: =MATCH(A6,SampleSuperstore[Postal Code],0) -> 13 | C6: {=INDEX(SampleSuperstore[Region],'Index + Match'!B6)} -> South | F6: 28027 | G6: =INDEX(SampleSuperstore[City],MATCH('Index + Match'!F6,SampleSuperstore[Postal Code],0)) -> Concord
A7: 98103 | B7: =MATCH(A7,SampleSuperstore[Postal Code],0) -> 14 | C7: {=INDEX(SampleSuperstore[Region],'Index + Match'!B7)} -> West | F7: 98103 | G7: =INDEX(SampleSuperstore[City],MATCH('Index + Match'!F7,SampleSuperstore[Postal Code],0)) -> Seattle
A8: 76106 | B8: =MATCH(A8,SampleSuperstore[Postal Code],0) -> 15 | C8: {=INDEX(SampleSuperstore[Region],'Index + Match'!B8)} -> Central | F8: 76106 | G8: =INDEX(SampleSuperstore[City],MATCH('Index + Match'!F8,SampleSuperstore[Postal Code],0)) -> Fort Worth
A9: 53711 | B9: =MATCH(A9,SampleSuperstore[Postal Code],0) -> 17 | C9: {=INDEX(SampleSuperstore[Region],'Index + Match'!B9)} -> Central | F9: 53711 | G9: =INDEX(SampleSuperstore[City],MATCH('Index + Match'!F9,SampleSuperstore[Postal Code],0)) -> Madison
A10: 84084 | B10: =MATCH(A10,SampleSuperstore[Postal Code],0) -> 18 | C10: {=INDEX(SampleSuperstore[Region],'Index + Match'!B10)} -> West | F10: 84084 | G10: =INDEX(SampleSuperstore[City],MATCH('Index + Match'!F10,SampleSuperstore[Postal Code],0)) -> West Jordan
A11: 94109 | B11: =MATCH(A11,SampleSuperstore[Postal Code],0) -> 19 | C11: {=INDEX(SampleSuperstore[Region],'Index + Match'!B11)} -> West | F11: 94109 | G11: =INDEX(SampleSuperstore[City],MATCH('Index + Match'!F11,SampleSuperstore[Postal Code],0)) -> San Francisco
A12: 68025 | B12: =MATCH(A12,SampleSuperstore[Postal Code],0) -> 22 | C12: {=INDEX(SampleSuperstore[Region],'Index + Match'!B12)} -> Central | F12: 68025 | G12: =INDEX(SampleSuperstore[City],MATCH('Index + Match'!F12,SampleSuperstore[Postal Code],0)) -> Fremont
A13: 19140 | B13: =MATCH(A13,SampleSuperstore[Postal Code],0) -> 24 | C13: {=INDEX(SampleSuperstore[Region],'Index + Match'!B13)} -> East | F13: 19140 | G13: =INDEX(SampleSuperstore[City],MATCH('Index + Match'!F13,SampleSuperstore[Postal Code],0)) -> Philadelphia
A14: 84057 | B14: =MATCH(A14,SampleSuperstore[Postal Code],0) -> 25 | C14: {=INDEX(SampleSuperstore[Region],'Index + Match'!B14)} -> West | F14: 84057 | G14: =INDEX(SampleSuperstore[City],MATCH('Index + Match'!F14,SampleSuperstore[Postal Code],0)) -> Orem
... A632: 30188 | B632: =MATCH(A632,SampleSuperstore[Postal Code],0) -> 9882 | C632: {=INDEX(SampleSuperstore[Region],'Index + Match'!B632)} -> South | F632: 30188 | G632: =INDEX(SampleSuperstore[City],MATCH('Index + Match'!F632,SampleSuperstore[Postal Code],0)) -> Woodstock

Sheet Data Cleaning
A1: Ship Mode | B1: Segment | C1: Country | D1: City | E1: State | F1: Postal Code | G1: Region | H1: Category | I1: Sub-Category | J1: Sales | K1: Quantity | L1: Discount | M1: Profit | O1: TRIM City | P1: TRIM State | Q1: Gabung/Merge Column | R1: Split Column (1) | S1: Split Column (2) | T1: Split Column (3) | U1: Split Column (4) | V1: Split Column (5)
A2: Second Class | B2: Consumer | C2: United States | D2: Henderson | E2: Kentucky | F2: 42420 | G2: South | H2: Furniture | I2: Bookcases | J2: 26196 | K2: 2 | L2: 0 | M2: 419136 | O2: =TRIM(SampleSuperstore3[[#This Row],[City]]) -> Henderson | P2: =TRIM(SampleSuperstore3[[#This Row],[State]]) -> Kentucky | Q2: =_xlfn.CONCAT(O2," ",P2) -> Henderson Kentucky | R2: Henderson | S2: Kentucky
A3: Second Class | B3: Consumer | C3: United States | D3: Henderson | E3: Kentucky | F3: 42420 | G3: South | H3: Furniture | I3: Chairs | J3: 73194 | K3: 3 | L3: 0 | M3: 219582 | O3: =TRIM(SampleSuperstore3[[#This Row],[City]]) -> Henderson | P3: =TRIM(SampleSuperstore3[[#This Row],[State]]) -> Kentucky | Q3: =_xlfn.CONCAT(O3," ",P3) -> Henderson Kentucky | R3: Henderson | S3: Kentucky
A4: Second Class | B4: Corporate | C4: United States | D4: Los Angeles | E4: California | F4: 90036 | G4: West | H4: Office Supplies | I4: Labels | J4: 1462 | K4: 2 | L4: 0 | M4: 68714 | O4: =TRIM(SampleSuperstore3[[#This Row],[City]]) -> Los Angeles | P4: =TRIM(SampleSuperstore3[[#This Row],[State]]) -> California | Q4: =_xlfn.CONCAT(O4," ",P4) -> Los Angeles California | R4: Los | S4: Angeles | T4: California
A5: Standard Class | B5: Consumer | C5: United States | D5: Fort Lauderdale | E5: Florida | F5: 33311 | G5: South | H5: Furniture | I5: Tables | J5: 9575775 | K5: 5 | L5: 45 | M5: -383031 | O5: =TRIM(SampleSuperstore3[[#This Row],[City]]) -> Fort Lauderdale | P5: =TRIM(SampleSuperstore3[[#This Row],[State]]) -> Florida | Q5: =_xlfn.CONCAT(O5," ",P5) -> Fort Lauderdale Florida | R5: Los | S5: Angeles | T5: Florida
A6: Standard Class | B6: Consumer | C6: United States | D6: Fort Lauderdale | E6: Florida | F6: 33311 | G6: South | H6: Office Supplies | I6: Storage | J6: 22368 | K6: 2 | L6: 2 | M6: 25164 | O6: =TRIM(SampleSuperstore3[[#This Row],[City]]) -> Fort Lauderdale | P6: =TRIM(SampleSuperstore3[[#This Row],[State]]) -> Florida | Q6: =_xlfn.CONCAT(O6," ",P6) -> Fort Lauderdale Florida | R6: Fort | S6: Lauderdale | T6: Florida
A7: Standard Class | B7: Consumer | C7: United States | D7: Los Angeles | E7: California | F7: 90032 | G7: West | H7: Furniture | I7: Furnishings | J7: 4886 | K7: 7 | L7: 0 | M7: 141694 | O7: =TRIM(SampleSuperstore3[[#This Row],[City]]) -> Los Angeles | P7: =TRIM(SampleSuperstore3[[#This Row],[State]]) -> California | Q7: =_xlfn.CONCAT(O7," ",P7) -> Los Angeles California | R7: Fort | S7: Worth | T7: Texas
A8: Standard Class | B8: Consumer | C8: United States | D8: Los Angeles | E8: California | F8: 90032 | G8: West | H8: Office Supplies | I8: Art | J8: 728 | K8: 4 | L8: 0 | M8: 19656 | O8: =TRIM(SampleSuperstore3[[#This Row],[City]]) -> Los Angeles | P8: =TRIM(SampleSuperstore3[[#This Row],[State]]) -> California | Q8: =_xlfn.CONCAT(O8," ",P8) -> Los Angeles California | R8: Fort | S8: Worth | T8: Texas
A9: Standard Class | B9: Consumer | C9: United States | D9: Los Angeles | E9: California | F9: 90032 | G9: West | H9: Technology | I9: Phones | J9: 907152 | K9: 6 | L9: 2 | M9: 907152 | O9: =TRIM(SampleSuperstore3[[#This Row],[City]]) -> Los Angeles | P9: =TRIM(SampleSuperstore3[[#This Row],[State]]) -> California | Q9: =_xlfn.CONCAT(O9," ",P9) -> Los Angeles California | R9: Madison | S9: Wisconsin
A10: Standard Class | B10: Consumer | C10: United States | D10: Los Angeles | E10: California | F10: 90032 | G10: West | H10: Office Supplies | I10: Binders | J10: 18504 | K10: 3 | L10: 2 | M10: 57825 | O10: =TRIM(SampleSuperstore3[[#This Row],[City]]) -> Los Angeles | P10: =TRIM(SampleSuperstore3[[#This Row],[State]]) -> California | Q10: =_xlfn.CONCAT(O10," ",P10) -> Los Angeles California | R10: West | S10: Jordan | T10: Utah
A11: Standard Class | B11: Consumer | C11: United States | D11: Los Angeles | E11: California | F11: 90032 | G11: West | H11: Office Supplies | I11: Appliances | J11: 1149 | K11: 5 | L11: 0 | M11: 3447 | O11: =TRIM(SampleSuperstore3[[#This Row],[City]]) -> Los Angeles | P11: =TRIM(SampleSuperstore3[[#This Row],[State]]) -> California | Q11: =_xlfn.CONCAT(O11," ",P11) -> Los Angeles California | R11: Los | S11: Angeles | T11: California
A12: Standard Class | B12: Consumer | C12: United States | D12: Los Angeles | E12: California | F12: 90032 | G12: West | H12: Furniture | I12: Tables | J12: 1706184 | K12: 9 | L12: 2 | M12: 853092 | O12: =TRIM(SampleSuperstore3[[#This Row],[City]]) -> Los Angeles | P12: =TRIM(SampleSuperstore3[[#This Row],[State]]) -> California | Q12: =_xlfn.CONCAT(O12," ",P12) -> Los Angeles California | R12: Los | S12: Angeles | T12: California
A13: Standard Class | B13: Consumer | C13: United States | D13: Los Angeles | E13: California | F13: 90032 | G13: West | H13: Technology | I13: Phones | J13: 911424 | K13: 4 | L13: 2 | M13: 683568 | O13: =TRIM(SampleSuperstore3[[#This Row],[City]]) -> Los Angeles | P13: =TRIM(SampleSuperstore3[[#This Row],[State]]) -> California | Q13: =_xlfn.CONCAT(O13," ",P13) -> Los Angeles California | R13: Los | S13: Angeles | T13: California
A14: Standard Class | B14: Consumer | C14: United States | D14: Concord | E14: North Carolina | F14: 28027 | G14: South | H14: Office Supplies | I14: Paper | J14: 15552 | K14: 3 | L14: 2 | M14: 54432 | O14: =TRIM(SampleSuperstore3[[#This Row],[City]]) -> Concord | P14: =TRIM(SampleSuperstore3[[#This Row],[State]]) -> North Carolina | Q14: =_xlfn.CONCAT(O14," ",P14) -> Concord North Carolina | R14: Los | S14: Angeles | T14: California
A15: Standard Class | B15: Consumer | C15: United States | D15: Seattle | E15: Washington | F15: 98103 | G15: West | H15: Office Supplies | I15: Binders | J15: 407976 | K15: 3 | L15: 2 | M15: 1325922 | O15: =TRIM(SampleSuperstore3[[#This Row],[City]]) -> Seattle | P15: =TRIM(SampleSuperstore3[[#This Row],[State]]) -> Washington | Q15: =_xlfn.CONCAT(O15," ",P15) -> Seattle Washington | R15: Los | S15: Angeles | T15: California
A16: Standard Class | B16: Home Office | C16: United States | D16: Fort Worth | E16: Texas | F16: 76106 | G16: Central | H16: Office Supplies | I16: Appliances | J16: 6881 | K16: 5 | L16: 8 | M16: -123858 | O16: =TRIM(SampleSuperstore3[[#This Row],[City]]) -> Fort Worth | P16: =TRIM(SampleSuperstore3[[#This Row],[State]]) -> Texas | Q16: =_xlfn.CONCAT(O16," ",P16) -> Fort Worth Texas | R16: Los | S16: Angeles | T16: California
A17: Standard Class | B17: Home Office | C17: United States | D17: Fort Worth | E17: Texas | F17: 76106 | G17: Central | H17: Office Supplies | I17: Binders | J17: 2544 | K17: 3 | L17: 8 | M17: -3816 | O17: =TRIM(SampleSuperstore3[[#This Row],[City]]) -> Fort Worth | P17: =TRIM(SampleSuperstore3[[#This Row],[State]]) -> Texas | Q17: =_xlfn.CONCAT(O17," ",P17) -> Fort Worth Texas | R17: Los | S17: Angeles | T17: California
A18: Standard Class | B18: Consumer | C18: United States | D18: Madison | E18: Wisconsin | F18: 53711 | G18: Central | H18: Office Supplies | I18: Storage | J18: 66588 | K18: 6 | L18: 0 | M18: 133176 | O18: =TRIM(SampleSuperstore3[[#This Row],[City]]) -> Madison | P18: =TRIM(SampleSuperstore3[[#This Row],[State]]) -> Wisconsin | Q18: =_xlfn.CONCAT(O18," ",P18) -> Madison Wisconsin | R18: Concord | S18: North | T18: Carolina
A19: Second Class | B19: Consumer | C19: United States | D19: West Jordan | E19: Utah | F19: 84084 | G19: West | H19: Office Supplies | I19: Storage | J19: 555 | K19: 2 | L19: 0 | M19: 999 | O19: =TRIM(SampleSuperstore3[[#This Row],[City]]) -> West Jordan | P19: =TRIM(SampleSuperstore3[[#This Row],[State]]) -> Utah | Q19: =_xlfn.CONCAT(O19," ",P19) -> West Jordan Utah | R19: Seattle | S19: Washington
A20: Second Class | B20: Consumer | C20: United States | D20: San Francisco | E20: California | F20: 94109 | G20: West | H20: Office Supplies | I20: Art | J20: 856 | K20: 2 | L20: 0 | M20: 24824 | O20: =TRIM(SampleSuperstore3[[#This Row],[City]]) -> San Francisco | P20: =TRIM(SampleSuperstore3[[#This Row],[State]]) -> California | Q20: =_xlfn.CONCAT(O20," ",P20) -> San Francisco California | R20: Fort | S20: Worth | T20: Texas
A21: Second Class | B21: Consumer | C21: United States | D21: San Francisco | E21: California | F21: 94109 | G21: West | H21: Technology | I21: Phones | J21: 21348 | K21: 3 | L21: 2 | M21: 16011 | O21: =TRIM(SampleSuperstore3[[#This Row],[City]]) -> San Francisco | P21: =TRIM(SampleSuperstore3[[#This Row],[State]]) -> California | Q21: =_xlfn.CONCAT(O21," ",P21) -> San Francisco California | R21: West | S21: Jordan | T21: Utah
A22: Second Class | B22: Consumer | C22: United States | D22: San Francisco | E22: California | F22: 94109 | G22: West | H22: Office Supplies | I22: Binders | J22: 2272 | K22: 4 | L22: 2 | M22: 7384 | O22: =TRIM(SampleSuperstore3[[#This Row],[City]]) -> San Francisco | P22: =TRIM(SampleSuperstore3[[#This Row],[State]]) -> California | Q22: =_xlfn.CONCAT(O22," ",P22) -> San Francisco California | R22: San | S22: Francisco | T22: California
A23: Standard Class | B23: Corporate | C23: United States | D23: Fremont | E23: Nebraska | F23: 68025 | G23: Central | H23: Office Supplies | I23: Art | J23: 1946 | K23: 7 | L23: 0 | M23: 50596 | O23: =TRIM(SampleSuperstore3[[#This Row],[City]]) -> Fremont | P23: =TRIM(SampleSuperstore3[[#This Row],[State]]) -> Nebraska | Q23: =_xlfn.CONCAT(O23," ",P23) -> Fremont Nebraska | R23: San | S23: Francisco | T23: California
A24: Standard Class | B24: Corporate | C24: United States | D24: Fremont | E24: Nebraska | F24: 68025 | G24: Central | H24: Office Supplies | I24: Appliances | J24: 6034 | K24: 7 | L24: 0 | M24: 156884 | O24: =TRIM(SampleSuperstore3[[#This Row],[City]]) -> Fremont | P24: =TRIM(SampleSuperstore3[[#This Row],[State]]) -> Nebraska | Q24: =_xlfn.CONCAT(O24," ",P24) -> Fremont Nebraska | R24: San | S24: Francisco | T24: California
A25: Second Class | B25: Consumer | C25: United States | D25: Philadelphia | E25: Pennsylvania | F25: 19140 | G25: East | H25: Furniture | I25: Chairs | J25: 71372 | K25: 2 | L25: 3 | M25: -10196 | O25: =TRIM(SampleSuperstore3[[#This Row],[City]]) -> Philadelphia | P25: =TRIM(SampleSuperstore3[[#This Row],[State]]) -> Pennsylvania | Q25: =_xlfn.CONCAT(O25," ",P25) -> Philadelphia Pennsylvania | R25: Fremont | S25: Nebraska
A26: Standard Class | B26: Consumer | C26: United States | D26: Orem | E26: Utah | F26: 84057 | G26: West | H26: Furniture | I26: Tables | J26: 104463 | K26: 3 | L26: 0 | M26: 2402649 | O26: =TRIM(SampleSuperstore3[[#This Row],[City]]) -> Orem | P26: =TRIM(SampleSuperstore3[[#This Row],[State]]) -> Utah | Q26: =_xlfn.CONCAT(O26," ",P26) -> Orem Utah | R26: Fremont | S26: Nebraska
A27: Second Class | B27: Consumer | C27: United States | D27: Los Angeles | E27: California | F27: 90049 | G27: West | H27: Office Supplies | I27: Binders | J27: 11648 | K27: 2 | L27: 2 | M27: 42224 | O27: =TRIM(SampleSuperstore3[[#This Row],[City]]) -> Los Angeles | P27: =TRIM(SampleSuperstore3[[#This Row],[State]]) -> California | Q27: =_xlfn.CONCAT(O27," ",P27) -> Los Angeles California | R27: Philadelphia | S27: Pennsylvania
A28: Second Class | B28: Consumer | C28: United States | D28: Los Angeles | E28: California | F28: 90049 | G28: West | H28: Technology | I28: Accessories | J28: 9057 | K28: 3 | L28: 0 | M28: 117741 | O28: =TRIM(SampleSuperstore3[[#This Row],[City]]) -> Los Angeles | P28: =TRIM(SampleSuperstore3[[#This Row],[State]]) -> California | Q28: =_xlfn.CONCAT(O28," ",P28) -> Los Angeles California | R28: Orem | S28: Utah
A29: Standard Class | B29: Consumer | C29: United States | D29: Philadelphia | E29: Pennsylvania | F29: 19140 | G29: East | H29: Furniture | I29: Bookcases | J29: 308343 | K29: 7 | L29: 5 | M29: -16650522 | O29: =TRIM(SampleSuperstore3[[#This Row],[City]]) -> Philadelphia | P29: =TRIM(SampleSuperstore3[[#This Row],[State]]) -> Pennsylvania | Q29: =_xlfn.CONCAT(O29," ",P29) -> Philadelphia Pennsylvania | R29: Los | S29: Angeles | T29: California
A30: Standard Class | B30: Consumer | C30: United States | D30: Philadelphia | E30: Pennsylvania | F30: 19140 | G30: East | H30: Office Supplies | I30: Binders | J30: 9618 | K30: 2 | L30: 7 | M30: -70532 | O30: =TRIM(SampleSuperstore3[[#This Row],[City]]) -> Philadelphia | P30: =TRIM(SampleSuperstore3[[#This Row],[State]]) -> Pennsylvania | Q30: =_xlfn.CONCAT(O30," ",P30) -> Philadelphia Pennsylvania | R30: Los | S30: Angeles | T30: California
A31: Standard Class | B31: Consumer | C31: United States | D31: Philadelphia | E31: Pennsylvania | F31: 19140 | G31: East | H31: Furniture | I31: Furnishings | J31: 1242 | K31: 3 | L31: 2 | M31: 15525 | O31: =TRIM(SampleSuperstore3[[#This Row],[City]]) -> Philadelphia | P31: =TRIM(SampleSuperstore3[[#This Row],[State]]) -> Pennsylvania | Q31: =_xlfn.CONCAT(O31," ",P31) -> Philadelphia Pennsylvania | R31: Philadelphia | S31: Pennsylvania
A32: Standard Class | B32: Consumer | C32: United States | D32: Philadelphia | E32: Pennsylvania | F32: 19140 | G32: East | H32: Office Supplies | I32: Envelopes | J32: 3264 | K32: 2 | L32: 2 | M32: 11016 | O32: =TRIM(SampleSuperstore3[[#This Row],[City]]) -> Philadelphia | P32: =TRIM(SampleSuperstore3[[#This Row],[State]]) -> Pennsylvania | Q32: =_xlfn.CONCAT(O32," ",P32) -> Philadelphia Pennsylvania | R32: Philadelphia | S32: Pennsylvania
A33: Standard Class | B33: Consumer | C33: United States | D33: Philadelphia | E33: Pennsylvania | F33: 19140 | G33: East | H33: Office Supplies | I33: Art | J33: 86304 | K33: 6 | L33: 2 | M33: 97092 | O33: =TRIM(SampleSuperstore3[[#This Row],[City]]) -> Philadelphia | P33: =TRIM(SampleSuperstore3[[#This Row],[State]]) -> Pennsylvania | Q33: =_xlfn.CONCAT(O33," ",P33) -> Philadelphia Pennsylvania | R33: Philadelphia | S33: Pennsylvania
A34: Standard Class | B34: Consumer | C34: United States | D34: Philadelphia | E34: Pennsylvania | F34: 19140 | G34: East | H34: Office Supplies | I34: Binders | J34: 6858 | K34: 6 | L34: 7 | M34: -5715 | O34: =TRIM(SampleSuperstore3[[#This Row],[City]]) -> Philadelphia | P34: =TRIM(SampleSuperstore3[[#This Row],[State]]) -> Pennsylvania | Q34: =_xlfn.CONCAT(O34," ",P34) -> Philadelphia Pennsylvania | R34: Philadelphia | S34: Pennsylvania
A35: Standard Class | B35: Consumer | C35: United States | D35: Philadelphia | E35: Pennsylvania | F35: 19140 | G35: East | H35: Office Supplies | I35: Art | J35: 1576 | K35: 2 | L35: 2 | M35: 3546 | O35: =TRIM(SampleSuperstore3[[#This Row],[City]]) -> Philadelphia | P35: =TRIM(SampleSuperstore3[[#This Row],[State]]) -> Pennsylvania | Q35: =_xlfn.CONCAT(O35," ",P35) -> Philadelphia Pennsylvania | R35: Philadelphia | S35: Pennsylvania
A36: Second Class | B36: Home Office | C36: United States | D36: Houston | E36: Texas | F36: 77095 | G36: Central | H36: Office Supplies | I36: Paper | J36: 29472 | K36: 3 | L36: 2 | M36: 99468 | O36: =TRIM(SampleSuperstore3[[#This Row],[City]]) -> Houston | P36: =TRIM(SampleSuperstore3[[#This Row],[State]]) -> Texas | Q36: =_xlfn.CONCAT(O36," ",P36) -> Houston Texas | R36: Philadelphia | S36: Pennsylvania
A37: First Class | B37: Corporate | C37: United States | D37: Richardson | E37: Texas | F37: 75080 | G37: Central | H37: Technology | I37: Phones | J37: 1097544 | K37: 7 | L37: 2 | M37: 1234737 | O37: =TRIM(SampleSuperstore3[[#This Row],[City]]) -> Richardson | P37: =TRIM(SampleSuperstore3[[#This Row],[State]]) -> Texas | Q37: =_xlfn.CONCAT(O37," ",P37) -> Richardson Texas | R37: Philadelphia | S37: Pennsylvania
A38: First Class | B38: Corporate | C38: United States | D38: Richardson | E38: Texas | F38: 75080 | G38: Central | H38: Furniture | I38: Furnishings | J38: 19092 | K38: 5 | L38: 6 | M38: -147963 | O38: =TRIM(SampleSuperstore3[[#This Row],[City]]) -> Richardson | P38: =TRIM(SampleSuperstore3[[#This Row],[State]]) -> Texas | Q38: =_xlfn.CONCAT(O38," ",P38) -> Richardson Texas | R38: Houston | S38: Texas
A39: Standard Class | B39: Home Office | C39: United States | D39: Houston | E39: Texas | F39: 77041 | G39: Central | H39: Office Supplies | I39: Envelopes | J39: 113328 | K39: 9 | L39: 2 | M39: 35415 | O39: =TRIM(SampleSuperstore3[[#This Row],[City]]) -> Houston | P39: =TRIM(SampleSuperstore3[[#This Row],[State]]) -> Texas | Q39: =_xlfn.CONCAT(O39," ",P39) -> Houston Texas | R39: Richardson | S39: Texas
A40: Standard Class | B40: Home Office | C40: United States | D40: Houston | E40: Texas | F40: 77041 | G40: Central | H40: Furniture | I40: Bookcases | J40: 5323992 | K40: 3 | L40: 32 | M40: -469764 | O40: =TRIM(SampleSuperstore3[[#This Row],[City]]) -> Houston | P40: =TRIM(SampleSuperstore3[[#This Row],[State]]) -> Texas | Q40: =_xlfn.CONCAT(O40," ",P40) -> Houston Texas | R40: Richardson | S40: Texas
...

Sheet Data Validation
A1: Ship Mode | B1: Segment | C1: Country | D1: Sales
A2: First Class | B2: =VLOOKUP(A2,SampleSuperstore3[],2,0) -> Corporate | C2: =VLOOKUP(A2,SampleSuperstore3[],3,0) -> United States | D2: =VLOOKUP(A2,SampleSuperstore3[],10,0) -> 1097544

Sheet Pivot Table
A1: Sales By Region | D1: Profit By Category | G1: Volume Of Transaction By Segment
A3: Row Labels | B3: Sum of Sales | D3: Row Labels | E3: Sum of Profit | G3: Row Labels | H3: Count of Segment
A4: West | B4: 365337643 | D4: Technology | E4: 964660095 | G4: Consumer | H4: 5191
A5: Central | B5: 321360741 | D5: Office Supplies | E5: 775994074 | G5: Corporate | H5: 3020
A6: East | B6: 292543756 | D6: Furniture | E6: 59222369 | G6: Home Office | H6: 1783
A7: South | B7: 152349580 | D7: Grand Total | E7: 1799876538 | G7: Grand Total | H7: 9994
A8: Grand Total | B8: 1131591720

Sheet Summary
A1: Ship Mode | B1: Segment | C1: Country | D1: City | E1: State | F1: Postal Code | G1: Region | H1: Category | I1: Sub-Category | J1: Sales | K1: Quantity | L1: Discount | M1: Profit
A2: Second Class | B2: Consumer | C2: United States | D2: Henderson | E2: Kentucky | F2: 42420 | G2: South | H2: Furniture | I2: Bookcases | J2: 26196 | K2: 2 | L2: 0 | M2: 419136 | O2: Tabel Disamping Telah Saya Seleksi dengan mengasumsikan "Postal Code" sebagai Unique ID
A3: Second Class | B3: Corporate | C3: United States | D3: Los Angeles | E3: California | F3: 90036 | G3: West | H3: Office Supplies | I3: Labels | J3: 1462 | K3: 2 | L3: 0 | M3: 68714
A4: Standard Class | B4: Consumer | C4: United States | D4: Fort Lauderdale | E4: Florida | F4: 33311 | G4: South | H4: Furniture | I4: Tables | J4: 9575775 | K4: 5 | L4: 45 | M4: -383031
A5: Standard Class | B5: Consumer | C5: United States | D5: Los Angeles | E5: California | F5: 90032 | G5: West | H5: Furniture | I5: Furnishings | J5: 4886 | K5: 7 | L5: 0 | M5: 141694 | O5: Selection Interactive Table
A6: Standard Class | B6: Consumer | C6: United States | D6: Concord | E6: North Carolina | F6: 28027 | G6: South | H6: Office Supplies | I6: Paper | J6: 15552 | K6: 3 | L6: 2 | M6: 54432 | O6: Postal Code | P6: 49201 | Q6: Profit
A7: Standard Class | B7: Consumer | C7: United States | D7: Seattle | E7: Washington | F7: 98103 | G7: West | H7: Office Supplies | I7: Binders | J7: 407976 | K7: 3 | L7: 2 | M7: 1325922 | O7: Category | P7: =VLOOKUP(P6,$F$2:$M$632,3,0) -> Office Supplies
A8: Standard Class | B8: Home Office | C8: United States | D8: Fort Worth | E8: Texas | F8: 76106 | G8: Central | H8: Office Supplies | I8: Appliances | J8: 6881 | K8: 5 | L8: 8 | M8: -123858 | O8: First Category | P8: {=TRANSPOSE(_xlfn.TEXTSPLIT(P7," "))} -> Office | Q8: =VLOOKUP(P6,$F$2:$M$632,8,0) -> 8763
A9: Standard Class | B9: Consumer | C9: United States | D9: Madison | E9: Wisconsin | F9: 53711 | G9: Central | H9: Office Supplies | I9: Storage | J9: 66588 | K9: 6 | L9: 0 | M9: 133176 | O9: Second Category | P9: Supplies | Q9: Index
A10: Second Class | B10: Consumer | C10: United States | D10: West Jordan | E10: Utah | F10: 84084 | G10: West | H10: Office Supplies | I10: Storage | J10: 555 | K10: 2 | L10: 0 | M10: 999 | O10: City | P10: =INDEX(D2:D632,MATCH(P6,F2:F632,0)) -> Jackson | Q10: =MATCH(P6,F2:F632,0) -> 31
A11: Second Class | B11: Consumer | C11: United States | D11: San Francisco | E11: California | F11: 94109 | G11: West | H11: Office Supplies | I11: Art | J11: 856 | K11: 2 | L11: 0 | M11: 24824
A12: Standard Class | B12: Corporate | C12: United States | D12: Fremont | E12: Nebraska | F12: 68025 | G12: Central | H12: Office Supplies | I12: Art | J12: 1946 | K12: 7 | L12: 0 | M12: 50596
A13: Second Class | B13: Consumer | C13: United States | D13: Philadelphia | E13: Pennsylvania | F13: 19140 | G13: East | H13: Furniture | I13: Chairs | J13: 71372 | K13: 2 | L13: 3 | M13: -10196 | O13: Sumber Data untuk tabel Pivot berikut diambil dari sheet Summary ini
A14: Standard Class | B14: Consumer | C14: United States | D14: Orem | E14: Utah | F14: 84057 | G14: West | H14: Furniture | I14: Tables | J14: 104463 | K14: 3 | L14: 0 | M14: 2402649
A15: Second Class | B15: Consumer | C15: United States | D15: Los Angeles | E15: California | F15: 90049 | G15: West | H15: Office Supplies | I15: Binders | J15: 11648 | K15: 2 | L15: 2 | M15: 42224 | O15: Sales By Region | R15: Profit By Category | U15: Volume Of Transaction By Segment
A16: Second Class | B16: Home Office | C16: United States | D16: Houston | E16: Texas | F16: 77095 | G16: Central | H16: Office Supplies | I16: Paper | J16: 29472 | K16: 3 | L16: 2 | M16: 99468
A17: First Class | B17: Corporate | C17: United States | D17: Richardson | E17: Texas | F17: 75080 | G17: Central | H17: Technology | I17: Phones | J17: 1097544 | K17: 7 | L17: 2 | M17: 1234737 | O17: Region | P17: Total Sales | R17: Category | S17: Total Profit | U17: Segment | V17: Jumlah Segment
A18: Standard Class | B18: Home Office | C18: United States | D18: Houston | E18: Texas | F18: 77041 | G18: Central | H18: Office Supplies | I18: Envelopes | J18: 113328 | K18: 9 | L18: 2 | M18: 35415 | O18: South | P18: 22500924 | R18: Office Supplies | S18: 52091950 | U18: Consumer | V18: 337
A19: Standard Class | B19: Corporate | C19: United States | D19: Naperville | E19: Illinois | F19: 60540 | G19: Central | H19: Technology | I19: Phones | J19: 147168 | K19: 4 | L19: 2 | M19: 165564 | O19: Central | P19: 16571262 | R19: Furniture | S19: 12555556 | U19: Corporate | V19: 193
A20: Standard Class | B20: Corporate | C20: United States | D20: Melbourne | E20: Florida | F20: 32935 | G20: South | H20: Office Supplies | I20: Storage | J20: 95616 | K20: 2 | L20: 2 | M20: 95616 | O20: West | P20: 15754624 | R20: Technology | S20: 10031089 | U20: Home Office | V20: 101
A21: First Class | B21: Corporate | C21: United States | D21: Eagan | E21: Minnesota | F21: 55122 | G21: Central | H21: Technology | I21: Accessories | J21: 4598 | K21: 2 | L21: 0 | M21: 197714 | O21: East | P21: 7841244 | R21: Grand Total | S21: 74678595 | U21: Grand Total | V21: 631
A22: Second Class | B22: Consumer | C22: United States | D22: Westland | E22: Michigan | F22: 48185 | G22: Central | H22: Office Supplies | I22: Storage | J22: 21196 | K22: 4 | L22: 0 | M22: 84784 | O22: Grand Total | P22: 62668054
A23: Standard Class | B23: Consumer | C23: United States | D23: Dover | E23: Delaware | F23: 19901 | G23: East | H23: Technology | I23: Accessories | J23: 45 | K23: 3 | L23: 0 | M23: 495
A24: Standard Class | B24: Consumer | C24: United States | D24: New Albany | E24: Indiana | F24: 47150 | G24: Central | H24: Office Supplies | I24: Binders | J24: 3822 | K24: 6 | L24: 0 | M24: 179634 | O24: Region South memiliki total penjualan | R24: Category Office Supplies | U24: Transaction dari Segment Home Office
A25: Standard Class | B25: Corporate | C25: United States | D25: New York City | E25: New York | F25: 10024 | G25: East | H25: Office Supplies | I25: Fasteners | J25: 1526 | K25: 7 | L25: 0 | M25: 62566 | O25: tertinggi dibandingkan dengan region | R25: menghasilkan keuntungan | U25: memiliki volume/jumlah terendah
A26: First Class | B26: Consumer | C26: United States | D26: Troy | E26: New York | F26: 12180 | G26: East | H26: Office Supplies | I26: Storage | J26: 20856 | K26: 6 | L26: 0 | M26: 5214 | O26: lainnya. | R26: terbesar. | U26: dibandingkan dengan Consumer &
A27: Standard Class | B27: Consumer | C27: United States | D27: Los Angeles | E27: California | F27: 90004 | G27: West | H27: Technology | I27: Accessories | J27: 1398 | K27: 2 | L27: 0 | M27: 61512 | U27: Corporate.
A28: Standard Class | B28: Home Office | C28: United States | D28: Chicago | E28: Illinois | F28: 60610 | G28: Central | H28: Furniture | I28: Chairs | J28: 213115 | K28: 5 | L28: 3 | M28: -152225
A29: Standard Class | B29: Corporate | C29: United States | D29: Gilbert | E29: Arizona | F29: 85234 | G29: West | H29: Office Supplies | I29: Art | J29: 1113024 | K29: 8 | L29: 2 | M29: 1113024
A30: First Class | B30: Consumer | C30: United States | D30: Springfield | E30: Virginia | F30: 22153 | G30: South | H30: Office Supplies | I30: Paper | J30: 7588 | K30: 2 | L30: 0 | M30: 356636
A31: Standard Class | B31: Consumer | C31: United States | D31: New York City | E31: New York | F31: 10009 | G31: East | H31: Office Supplies | I31: Binders | J31: 4616 | K31: 1 | L31: 2 | M31: 1731
A32: Second Class | B32: Consumer | C32: United States | D32: Jackson | E32: Michigan | F32: 49201 | G32: Central | H32: Office Supplies | I32: Paper | J32: 1905 | K32: 3 | L32: 0 | M32: 8763
A33: Standard Class | B33: Consumer | C33: United States | D33: Memphis | E33: Tennessee | F33: 38109 | G33: South | H33: Furniture | I33: Chairs | J33: 831936 | K33: 8 | L33: 2 | M33: -1143912
A34: Second Class | B34: Consumer | C34: United States | D34: Houston | E34: Texas | F34: 77070 | G34: Central | H34: Furniture | I34: Furnishings | J34: 193 | K34: 5 | L34: 6 | M34: -14475
A35: First Class | B35: Corporate | C35: United States | D35: Decatur | E35: Alabama | F35: 35601 | G35: South | H35: Office Supplies | I35: Appliances | J35: 20816 | K35: 1 | L35: 0 | M35: 562032
A36: Standard Class | B36: Consumer | C36: United States | D36: San Francisco | E36: California | F36: 94122 | G36: West | H36: Office Supplies | I36: Art | J36: 149 | K36: 5 | L36: 0 | M36: 4172
A37: Standard Class | B37: Corporate | C37: United States | D37: Durham | E37: North Carolina | F37: 27707 | G37: South | H37: Office Supplies | I37: Envelopes | J37: 200984 | K37: 7 | L37: 2 | M37: 628075
A38: First Class | B38: Home Office | C38: United States | D38: Chicago | E38: Illinois | F38: 60623 | G38: Central | H38: Office Supplies | I38: Storage | J38: 230376 | K38: 3 | L38: 2 | M38: -489549
A39: Second Class | B39: Consumer | C39: United States | D39: Columbia | E39: South Carolina | F39: 29203 | G39: South | H39: Furniture | I39: Chairs | J39: 30196 | K39: 2 | L39: 0 | M39: 332156
... A632: First Class | B632: Consumer | C632: United States | D632: Woodstock | E632: Georgia | F632: 30188 | G632: South | H632: Office Supplies | I632: Binders | J632: 1404 | K632: 3 | L632: 0 | M632: 67392
